2024-05-05 15:19:09,407 - root - INFO - This is Question 2 start
2024-05-05 15:19:12,832 - root - INFO - This is Start of Question 3
2024-05-05 15:19:12,834 - root - ERROR - Except block from Question 3 executed
Traceback (most recent call last):
  File "C:\Users\pratik\AppData\Local\Temp\ipykernel_29792\3002810753.py", line 5, in <module>
    with open('sample.txt','r') as f:
         ^^^^^^^^^^^^^^^^^^^^^^
  File "C:\Users\pratik\AppData\Roaming\Python\Python312\site-packages\IPython\core\interactiveshell.py", line 308, in _modified_open
    return io_open(file, *args, **kwargs)
           ^^^^^^^^^^^^^^^^^^^^^^^^^^^^^^
FileNotFoundError: [Errno 2] No such file or directory: 'sample.txt'
2024-05-05 15:19:12,835 - root - INFO - Finally Block from Question 3 executed
2024-05-05 15:19:18,390 - root - INFO - This is Start of function divide
2024-05-05 15:19:18,390 - root - INFO - Try Block executed
2024-05-05 15:19:18,390 - root - INFO - Else Block executed
2024-05-05 15:19:20,294 - root - INFO - This is Start of function divide
2024-05-05 15:19:20,294 - root - INFO - Try Block executed
2024-05-05 15:19:20,295 - root - INFO - Else Block executed
2024-05-05 15:19:22,458 - root - INFO - This is Start of function divide
2024-05-05 15:19:22,459 - root - ERROR - Except block executed
Traceback (most recent call last):
  File "C:\Users\pratik\AppData\Local\Temp\ipykernel_29792\3619439627.py", line 9, in divide
    result = a/b
             ~^~
ZeroDivisionError: division by zero
2024-05-05 15:19:25,183 - root - INFO - This is Start of function divide
2024-05-05 15:19:25,183 - root - ERROR - Except block executed
Traceback (most recent call last):
  File "C:\Users\pratik\AppData\Local\Temp\ipykernel_29792\3619439627.py", line 9, in divide
    result = a/b
             ~^~
TypeError: unsupported operand type(s) for /: 'str' and 'int'
2024-05-05 15:19:27,708 - root - INFO - Explaining Finally block code of Question 3
2024-05-05 15:19:27,708 - root - ERROR - Except block executed
Traceback (most recent call last):
  File "C:\Users\pratik\AppData\Local\Temp\ipykernel_29792\2074260654.py", line 6, in <module>
    c = a + b
        ~~^~~
TypeError: unsupported operand type(s) for +: 'int' and 'str'
2024-05-05 15:19:27,710 - root - INFO - Finally Block executed
2024-05-05 15:19:34,595 - root - INFO - This is start of mob_num function from Question 3 Raise explaination
2024-05-05 15:19:53,275 - root - INFO - Question 5 , case 1 started
2024-05-05 15:19:53,276 - root - INFO - No Error occured
2024-05-05 15:19:56,137 - root - INFO - Question 5 , case 3 started
2024-05-05 15:19:56,137 - root - ERROR - Percentage not in range
2024-05-05 15:20:03,484 - root - INFO - Test Case 1 , Question 6
2024-05-05 15:20:03,484 - root - INFO - Validate pan function started
2024-05-05 15:20:03,484 - root - INFO - PAN Card number is Valid
2024-05-05 15:20:03,486 - root - INFO - Try Block executed
2024-05-05 15:20:05,895 - root - INFO - Test Case 2 , Question 6
2024-05-05 15:20:05,896 - root - INFO - Validate pan function started
2024-05-05 15:20:05,896 - root - ERROR - Surname error , Surname cannot have numbers
2024-05-05 15:20:05,896 - root - ERROR - Except block executed
Traceback (most recent call last):
  File "C:\Users\pratik\AppData\Local\Temp\ipykernel_29792\2302266496.py", line 6, in <module>
    validate_pan_number(surname,pan)
  File "C:\Users\pratik\AppData\Local\Temp\ipykernel_29792\2058743615.py", line 9, in validate_pan_number
    raise validatePAN('Surname cannot consist of numbers')
validatePAN: Surname cannot consist of numbers
2024-05-05 15:20:07,514 - root - INFO - Test Case 3 , Question 6
2024-05-05 15:20:07,515 - root - INFO - Validate pan function started
2024-05-05 15:20:07,515 - root - ERROR - PAN Number length is not equal to 10
2024-05-05 15:20:07,515 - root - ERROR - Except block executed
Traceback (most recent call last):
  File "C:\Users\pratik\AppData\Local\Temp\ipykernel_29792\3688708175.py", line 6, in <module>
    validate_pan_number(surname,pan)
  File "C:\Users\pratik\AppData\Local\Temp\ipykernel_29792\2058743615.py", line 14, in validate_pan_number
    raise validatePAN('Length of PAN Card should be 10 digits')
validatePAN: Length of PAN Card should be 10 digits
2024-05-05 15:20:14,946 - root - INFO - Test Case 4 , Question 6
2024-05-05 15:20:14,946 - root - INFO - Validate pan function started
2024-05-05 15:20:14,946 - root - ERROR - First 3 letters of PAN Number are not characters
2024-05-05 15:20:14,946 - root - ERROR - Except block executed
Traceback (most recent call last):
  File "C:\Users\pratik\AppData\Local\Temp\ipykernel_29792\868844381.py", line 6, in <module>
    validate_pan_number(surname,pan)
  File "C:\Users\pratik\AppData\Local\Temp\ipykernel_29792\2058743615.py", line 19, in validate_pan_number
    raise validatePAN('First Three characters of Pan Card Must be Letters')
validatePAN: First Three characters of Pan Card Must be Letters
2024-05-05 15:20:17,466 - root - INFO - Test Case 5 , Question 6
2024-05-05 15:20:17,466 - root - INFO - Validate pan function started
2024-05-05 15:20:17,466 - root - ERROR - 1st Letter of Surname and 5th Letter of PAN not matching
2024-05-05 15:20:17,467 - root - ERROR - Except block executed
Traceback (most recent call last):
  File "C:\Users\pratik\AppData\Local\Temp\ipykernel_29792\2808962196.py", line 6, in <module>
    validate_pan_number(surname,pan)
  File "C:\Users\pratik\AppData\Local\Temp\ipykernel_29792\2058743615.py", line 30, in validate_pan_number
    raise validatePAN("First Digit of surname not matching with 5th Letter of pan")
validatePAN: First Digit of surname not matching with 5th Letter of pan
2024-05-05 15:20:21,030 - root - INFO - Test Case 6 , Question 6
2024-05-05 15:20:21,030 - root - INFO - Validate pan function started
2024-05-05 15:20:21,031 - root - ERROR - Characters 6 to 9 not numeric
2024-05-05 15:20:21,031 - root - ERROR - Except block executed
Traceback (most recent call last):
  File "C:\Users\pratik\AppData\Local\Temp\ipykernel_29792\3642342128.py", line 6, in <module>
    validate_pan_number(surname,pan)
  File "C:\Users\pratik\AppData\Local\Temp\ipykernel_29792\2058743615.py", line 35, in validate_pan_number
    raise validatePAN("Characters from 6 to 9 should be numbers")
validatePAN: Characters from 6 to 9 should be numbers
2024-05-05 15:20:23,224 - root - INFO - Test Case 8 , Question 6
2024-05-05 15:20:23,225 - root - INFO - Validate pan function started
2024-05-05 15:20:23,226 - root - INFO - PAN Card number is Valid
2024-05-05 15:20:23,227 - root - INFO - Try Block executed
